<?xml version="1.0" encoding="UTF-8"?>
<testng-results skipped="0" failed="2" ignored="0" total="6" passed="4">
  <reporter-output>
  </reporter-output>
  <suite name="Default suite" duration-ms="3412" started-at="2018-12-07T11:27:24Z" finished-at="2018-12-07T11:27:27Z">
    <groups>
    </groups>
    <test name="Default test" duration-ms="3412" started-at="2018-12-07T11:27:24Z" finished-at="2018-12-07T11:27:27Z">
      <class name="com.qa.tests.PostAPITest">
        <test-method status="FAIL" signature="IDP_User_info_call()[pri:0, instance:com.qa.tests.PostAPITest@c038203]" name="IDP_User_info_call" duration-ms="1198" started-at="2018-12-07T11:27:24Z" finished-at="2018-12-07T11:27:25Z">
          <exception class="java.lang.AssertionError">
            <message>
              <![CDATA[expected [200] but found [401]]]>
            </message>
            <full-stacktrace>
              <![CDATA[java.lang.AssertionError: expected [200] but found [401]
at org.testng.Assert.fail(Assert.java:96)
at org.testng.Assert.failNotEquals(Assert.java:776)
at org.testng.Assert.assertEqualsImpl(Assert.java:137)
at org.testng.Assert.assertEquals(Assert.java:118)
at org.testng.Assert.assertEquals(Assert.java:652)
at org.testng.Assert.assertEquals(Assert.java:662)
at com.qa.tests.PostAPITest.IDP_User_info_call(PostAPITest.java:205)
at sun.reflect.NativeMethodAccessorImpl.invoke0(Native Method)
at sun.reflect.NativeMethodAccessorImpl.invoke(Unknown Source)
at sun.reflect.DelegatingMethodAccessorImpl.invoke(Unknown Source)
at java.lang.reflect.Method.invoke(Unknown Source)
at org.testng.internal.MethodInvocationHelper.invokeMethod(MethodInvocationHelper.java:124)
at org.testng.internal.Invoker.invokeMethod(Invoker.java:583)
at org.testng.internal.Invoker.invokeTestMethod(Invoker.java:719)
at org.testng.internal.Invoker.invokeTestMethods(Invoker.java:989)
at org.testng.internal.TestMethodWorker.invokeTestMethods(TestMethodWorker.java:125)
at org.testng.internal.TestMethodWorker.run(TestMethodWorker.java:109)
at org.testng.TestRunner.privateRun(TestRunner.java:648)
at org.testng.TestRunner.run(TestRunner.java:505)
at org.testng.SuiteRunner.runTest(SuiteRunner.java:455)
at org.testng.SuiteRunner.runSequentially(SuiteRunner.java:450)
at org.testng.SuiteRunner.privateRun(SuiteRunner.java:415)
at org.testng.SuiteRunner.run(SuiteRunner.java:364)
at org.testng.SuiteRunnerWorker.runSuite(SuiteRunnerWorker.java:52)
at org.testng.SuiteRunnerWorker.run(SuiteRunnerWorker.java:84)
at org.testng.TestNG.runSuitesSequentially(TestNG.java:1208)
at org.testng.TestNG.runSuitesLocally(TestNG.java:1137)
at org.testng.TestNG.runSuites(TestNG.java:1049)
at org.testng.TestNG.run(TestNG.java:1017)
at org.testng.remote.AbstractRemoteTestNG.run(AbstractRemoteTestNG.java:114)
at org.testng.remote.RemoteTestNG.initAndRun(RemoteTestNG.java:251)
at org.testng.remote.RemoteTestNG.main(RemoteTestNG.java:77)
]]>
            </full-stacktrace>
          </exception> <!-- java.lang.AssertionError -->
          <reporter-output>
          </reporter-output>
        </test-method> <!-- IDP_User_info_call -->
        <test-method status="PASS" signature="Incorrectusername()[pri:0, instance:com.qa.tests.PostAPITest@c038203]" name="Incorrectusername" duration-ms="417" started-at="2018-12-07T11:27:25Z" finished-at="2018-12-07T11:27:25Z">
          <reporter-output>
          </reporter-output>
        </test-method> <!-- Incorrectusername -->
        <test-method status="PASS" signature="InvalidPassword()[pri:0, instance:com.qa.tests.PostAPITest@c038203]" name="InvalidPassword" duration-ms="394" started-at="2018-12-07T11:27:25Z" finished-at="2018-12-07T11:27:26Z">
          <reporter-output>
          </reporter-output>
        </test-method> <!-- InvalidPassword -->
        <test-method status="PASS" signature="Loginget()[pri:0, instance:com.qa.tests.PostAPITest@c038203]" name="Loginget" duration-ms="596" started-at="2018-12-07T11:27:26Z" finished-at="2018-12-07T11:27:26Z">
          <reporter-output>
          </reporter-output>
        </test-method> <!-- Loginget -->
        <test-method status="PASS" signature="Loginpost()[pri:0, instance:com.qa.tests.PostAPITest@c038203]" name="Loginpost" duration-ms="388" started-at="2018-12-07T11:27:26Z" finished-at="2018-12-07T11:27:27Z">
          <reporter-output>
          </reporter-output>
        </test-method> <!-- Loginpost -->
        <test-method status="FAIL" signature="accesstoken_for_invalid_client_id()[pri:0, instance:com.qa.tests.PostAPITest@c038203]" name="accesstoken_for_invalid_client_id" duration-ms="397" started-at="2018-12-07T11:27:27Z" finished-at="2018-12-07T11:27:27Z">
          <exception class="java.lang.AssertionError">
            <message>
              <![CDATA[expected [200] but found [400]]]>
            </message>
            <full-stacktrace>
              <![CDATA[java.lang.AssertionError: expected [200] but found [400]
at org.testng.Assert.fail(Assert.java:96)
at org.testng.Assert.failNotEquals(Assert.java:776)
at org.testng.Assert.assertEqualsImpl(Assert.java:137)
at org.testng.Assert.assertEquals(Assert.java:118)
at org.testng.Assert.assertEquals(Assert.java:652)
at org.testng.Assert.assertEquals(Assert.java:662)
at com.qa.tests.PostAPITest.accesstoken_for_invalid_client_id(PostAPITest.java:157)
at sun.reflect.NativeMethodAccessorImpl.invoke0(Native Method)
at sun.reflect.NativeMethodAccessorImpl.invoke(Unknown Source)
at sun.reflect.DelegatingMethodAccessorImpl.invoke(Unknown Source)
at java.lang.reflect.Method.invoke(Unknown Source)
at org.testng.internal.MethodInvocationHelper.invokeMethod(MethodInvocationHelper.java:124)
at org.testng.internal.Invoker.invokeMethod(Invoker.java:583)
at org.testng.internal.Invoker.invokeTestMethod(Invoker.java:719)
at org.testng.internal.Invoker.invokeTestMethods(Invoker.java:989)
at org.testng.internal.TestMethodWorker.invokeTestMethods(TestMethodWorker.java:125)
at org.testng.internal.TestMethodWorker.run(TestMethodWorker.java:109)
at org.testng.TestRunner.privateRun(TestRunner.java:648)
at org.testng.TestRunner.run(TestRunner.java:505)
at org.testng.SuiteRunner.runTest(SuiteRunner.java:455)
at org.testng.SuiteRunner.runSequentially(SuiteRunner.java:450)
at org.testng.SuiteRunner.privateRun(SuiteRunner.java:415)
at org.testng.SuiteRunner.run(SuiteRunner.java:364)
at org.testng.SuiteRunnerWorker.runSuite(SuiteRunnerWorker.java:52)
at org.testng.SuiteRunnerWorker.run(SuiteRunnerWorker.java:84)
at org.testng.TestNG.runSuitesSequentially(TestNG.java:1208)
at org.testng.TestNG.runSuitesLocally(TestNG.java:1137)
at org.testng.TestNG.runSuites(TestNG.java:1049)
at org.testng.TestNG.run(TestNG.java:1017)
at org.testng.remote.AbstractRemoteTestNG.run(AbstractRemoteTestNG.java:114)
at org.testng.remote.RemoteTestNG.initAndRun(RemoteTestNG.java:251)
at org.testng.remote.RemoteTestNG.main(RemoteTestNG.java:77)
]]>
            </full-stacktrace>
          </exception> <!-- java.lang.AssertionError -->
          <reporter-output>
          </reporter-output>
        </test-method> <!-- accesstoken_for_invalid_client_id -->
      </class> <!-- com.qa.tests.PostAPITest -->
    </test> <!-- Default test -->
  </suite> <!-- Default suite -->
</testng-results>
